// This program tests the basic functionality of exceptions.

class theMain {

  method foo() {
    try {
      throw 5;
      print(17);      // should not be printed
    }
    catch(e) {
      throw e + 2;    // throws 7
    }
    throw 1;          // should not be reached
  }

  method theMain() {
    try {
      foo();
    }
    catch(e) {
      print(e,"\n");  // should print 7
    }
  }

}

// 7
